<sdf version='1.6'>
  <model name='rover_uwb'>
    <pose>0 3 0 0 -0 0</pose>
    <link name='base_link'>
      <pose>0 -0 0.175 0 -0 0</pose>
      <inertial>
        <mass>1.14395</mass>
        <inertia>
          <ixx>0.126164</ixx>
          <ixy>0</ixy>
          <ixz>0</ixz>
          <iyy>0.416519</iyy>
          <iyz>0</iyz>
          <izz>0.481014</izz>
        </inertia>
      </inertial>
      <visual name='visual'>
        <geometry>
          <box>
            <size>1 1 0.568726</size>
          </box>
        </geometry>
      </visual>
      <collision name='collision'>
        <geometry>
          <box>
            <size>1 1 0.568726</size>
          </box>
        </geometry>
        <surface>
          <friction>
            <ode>
              <mu>0.6</mu>
              <mu2>0.6</mu2>
              <slip1>0</slip1>
              <slip2>0</slip2>
            </ode>
          </friction>
          <contact>
            <ode>
              <soft_cfm>0</soft_cfm>
              <soft_erp>0.2</soft_erp>
              <kp>1e+13</kp>
              <kd>1</kd>
              <max_vel>0.01</max_vel>
              <min_depth>0.01</min_depth>
            </ode>
            <bullet>
              <soft_cfm>0</soft_cfm>
              <soft_erp>0.2</soft_erp>
              <kp>1e+13</kp>
              <kd>1</kd>
              <split_impulse>1</split_impulse>
              <split_impulse_penetration_threshold>-0.01</split_impulse_penetration_threshold>
            </bullet>
          </contact>
        </surface>
      </collision>
    </link>

    <link name='left_wheel'>
      <pose>0.25 0.3 -0.025 -1.5707 0 0</pose>
      <inertial>
        <mass>2</mass>
        <inertia>
          <ixx>0.145833</ixx>
          <ixy>0</ixy>
          <ixz>0</ixz>
          <iyy>0.145833</iyy>
          <iyz>0</iyz>
          <izz>0.125</izz>
        </inertia>
      </inertial>
      <visual name='visual'>
        <geometry>
          <sphere>
            <radius>0.2</radius>
          </sphere>
        </geometry>
      </visual>
      <collision name='collision'>
        <geometry>
          <sphere>
            <radius>0.2</radius>
          </sphere>
        </geometry>
        <surface>
          <friction>
            <ode>
              <mu>1</mu>
              <mu2>1</mu2>
              <slip1>0</slip1>
              <slip2>0</slip2>
            </ode>
          </friction>
          <contact>
            <ode>
              <soft_cfm>0</soft_cfm>
              <soft_erp>0.2</soft_erp>
              <kp>1e+13</kp>
              <kd>1</kd>
              <max_vel>0.01</max_vel>
              <min_depth>0.01</min_depth>
            </ode>
          </contact>
        </surface>
      </collision>
    </link>

    <link name='right_wheel'>
      <pose>0.25 -0.3 -0.025 -1.5707 0 0</pose>
      <inertial>
        <mass>2</mass>
        <inertia>
          <ixx>0.145833</ixx>
          <ixy>0</ixy>
          <ixz>0</ixz>
          <iyy>0.145833</iyy>
          <iyz>0</iyz>
          <izz>0.125</izz>
        </inertia>
      </inertial>
      <visual name='visual'>
        <geometry>
          <sphere>
            <radius>0.2</radius>
          </sphere>
        </geometry>
      </visual>
      <collision name='collision'>
        <geometry>
          <sphere>
            <radius>0.2</radius>
          </sphere>
        </geometry>
        <surface>
          <friction>
            <ode>
              <mu>1</mu>
              <mu2>1</mu2>
              <slip1>0</slip1>
              <slip2>0</slip2>
            </ode>
          </friction>
          <contact>
            <ode>
              <soft_cfm>0</soft_cfm>
              <soft_erp>0.2</soft_erp>
              <kp>1e+13</kp>
              <kd>1</kd>
              <max_vel>0.01</max_vel>
              <min_depth>0.01</min_depth>
            </ode>
          </contact>
        </surface>
      </collision>
    </link>

    <link name='caster'>
      <pose>-0.35 -0 -0.125 0 -0 0</pose>
      <inertial>
        <mass>1</mass>
        <inertia>
          <ixx>0.1</ixx>
          <ixy>0</ixy>
          <ixz>0</ixz>
          <iyy>0.1</iyy>
          <iyz>0</iyz>
          <izz>0.1</izz>
        </inertia>
      </inertial>
      <visual name='visual'>
        <geometry>
          <sphere>
            <radius>0.1</radius>
          </sphere>
        </geometry>
      </visual>
      <collision name='collision'>
        <geometry>
          <sphere>
            <radius>0.1</radius>
          </sphere>
        </geometry>
      </collision>
    </link>

    <link name='anchor_0'>
      <pose>-0.45 -0.45 0.5 0 -0 0</pose>
      <inertial>
        <mass>1</mass>
        <inertia>
          <ixx>0.1</ixx>
          <ixy>0</ixy>
          <ixz>0</ixz>
          <iyy>0.1</iyy>
          <iyz>0</iyz>
          <izz>0.1</izz>
        </inertia>
      </inertial>
      <visual name='visual'>
        <geometry>
          <box>
            <size>0.03 0.03 0.2</size>
          </box>
        </geometry>
      </visual>
      <collision name='collision'>
        <geometry>
          <box>
            <size>0.03 0.03 0.2</size>
          </box>
        </geometry>
      </collision>

    </link>


    <joint name='anchor_0_joint' type='fixed'>
      <parent>base_link</parent>
      <child>anchor_0</child>
      <axis>
        <xyz>0 0 1</xyz>
      </axis>
    </joint>


    <link name='anchor_1'>
      <pose>0.45 0.45 0.5 0 -0 0</pose>
      <inertial>
        <mass>1</mass>
        <inertia>
          <ixx>0.1</ixx>
          <ixy>0</ixy>
          <ixz>0</ixz>
          <iyy>0.1</iyy>
          <iyz>0</iyz>
          <izz>0.1</izz>
        </inertia>
      </inertial>
      <visual name='visual'>
        <geometry>
          <box>
            <size>0.03 0.03 0.2</size>
          </box>
        </geometry>
      </visual>
      <collision name='collision'>
        <geometry>
          <box>
            <size>0.03 0.03 0.2</size>
          </box>
        </geometry>
      </collision>
    </link>


    <joint name='anchor_1_joint' type='fixed'>
      <parent>base_link</parent>
      <child>anchor_1</child>
      <axis>
        <xyz>0 0 1</xyz>
      </axis>
    </joint>



    <link name='anchor_2'>
      <pose>-0.45 +0.45 0.5 0 -0 0</pose>
      <inertial>
        <mass>1</mass>
        <inertia>
          <ixx>0.1</ixx>
          <ixy>0</ixy>
          <ixz>0</ixz>
          <iyy>0.1</iyy>
          <iyz>0</iyz>
          <izz>0.1</izz>
        </inertia>
      </inertial>
      <visual name='visual'>
        <geometry>
          <box>
            <size>0.03 0.03 0.2</size>
          </box>
        </geometry>
      </visual>
      <collision name='collision'>
        <geometry>
          <box>
            <size>0.03 0.03 0.2</size>
          </box>
        </geometry>
      </collision>
    </link>


    <joint name='anchor_2_joint' type='fixed'>
      <parent>base_link</parent>
      <child>anchor_2</child>
      <axis>
        <xyz>0 0 1</xyz>
      </axis>
    </joint>
    
    
    <link name='anchor_3'>
      <pose>+0.45 -0.45 0.5 0 -0 0</pose>
      <inertial>
        <mass>1</mass>
        <inertia>
          <ixx>0.1</ixx>
          <ixy>0</ixy>
          <ixz>0</ixz>
          <iyy>0.1</iyy>
          <iyz>0</iyz>
          <izz>0.1</izz>
        </inertia>
      </inertial>
      <visual name='visual'>
        <geometry>
          <box>
            <size>0.03 0.03 0.2</size>
          </box>
        </geometry>
      </visual>
      <collision name='collision'>
        <geometry>
          <box>
            <size>0.03 0.03 0.2</size>
          </box>
        </geometry>
      </collision>
    </link>

    
    <joint name='anchor_3_joint' type='fixed'>
      <parent>base_link</parent>
      <child>anchor_3</child>
      <axis>
        <xyz>0 0 1</xyz>
      </axis>
    </joint> 

    <joint name='left_wheel_joint' type='revolute'>
      <parent>base_link</parent>
      <child>left_wheel</child>
      <axis>
        <xyz>0 0 1</xyz>
        <limit>
          <lower>-1.79769e+308</lower>
          <upper>1.79769e+308</upper>
        </limit>
      </axis>
    </joint>

    
    <link name='apriltag'>
      <pose frame=''>0 0 0.459 0 0 0</pose>
      <visual name='apriltag_Visual'>
        <geometry>
          <box>
            <size>0.2 0.2 0.01</size>
          </box>
        </geometry>
        <material>
          <script>
            <uri>model://Apriltag36_11_00000/materials/scripts</uri>
            <uri>model://Apriltag36_11_00000/materials/textures</uri>
            <name>Apriltag36_11_00000</name>
          </script>
        </material>
      </visual>
    </link>-->

    
    <joint name='apriltag_joint' type='fixed'>
      <parent>base_link</parent>
      <child>apriltag</child>
      <axis>
        <xyz>0 0 1</xyz>
      </axis>
    </joint>
  

    <joint name='right_wheel_joint' type='revolute'>
      <parent>base_link</parent>
      <child>right_wheel</child>
      <axis>
        <xyz>0 0 1</xyz>
        <limit>
          <lower>-1.79769e+308</lower>
          <upper>1.79769e+308</upper>
        </limit>
      </axis>
    </joint>

    <joint name='caster_wheel' type='ball'>
      <parent>base_link</parent>
      <child>caster</child>
    </joint>

    <plugin name='diff_drive' filename='libgazebo_ros_diff_drive.so'>

      <ros>
        <namespace>/rover
        </namespace>
      </ros>

      <!-- wheels -->
      <left_joint>left_wheel_joint</left_joint>
      <right_joint>right_wheel_joint</right_joint>

      <!-- kinematics -->
      <wheel_separation>1.25</wheel_separation>
      <wheel_diameter>0.6</wheel_diameter>

      <!-- limits -->
      <max_wheel_torque>100</max_wheel_torque>
      <max_wheel_acceleration>1.0</max_wheel_acceleration>

      <!-- output -->
      <publish_odom>true</publish_odom>
      <publish_odom_tf>true</publish_odom_tf>
      <publish_wheel_tf>true</publish_wheel_tf>

      <odometry_frame>odom_rover</odometry_frame>
      <robot_base_frame>base_link</robot_base_frame>

    </plugin>


    <plugin name="gazebo_ros_p3d" filename="libgazebo_ros_p3d.so">
      <ros>
        <namespace>/chassis</namespace>
      </ros>
      <body_name>base_link</body_name>
      <frame_name>world</frame_name>
      <update_rate>50</update_rate>
      <xyz_offset>0 0 0</xyz_offset>
      <rpy_offset>0 0 0</rpy_offset>
      <gaussian_noise>0</gaussian_noise>
    </plugin>

    <plugin name="gazebo_ros_uwb" filename="libros2_px4_gazebo_uwb.so">
      <link_name>anchor_0</link_name>
      <update_rate>20</update_rate>
      <reference_model_name>rover_uwb</reference_model_name>
      <reference_link_name>base_link</reference_link_name>
    </plugin>

    <plugin name="gazebo_ros_uwb" filename="libros2_px4_gazebo_uwb.so">
      <link_name>anchor_1</link_name>
      <update_rate>20</update_rate>
      <reference_model_name>rover_uwb</reference_model_name>
      <reference_link_name>base_link</reference_link_name>
    </plugin>

    <plugin name="gazebo_ros_uwb" filename="libros2_px4_gazebo_uwb.so">
      <link_name>anchor_2</link_name>
      <update_rate>20</update_rate>
      <reference_model_name>rover_uwb</reference_model_name>
      <reference_link_name>base_link</reference_link_name>
    </plugin>
    
    
    <plugin name="gazebo_ros_uwb" filename="libros2_px4_gazebo_uwb.so">
      <link_name>anchor_3</link_name>
      <update_rate>20</update_rate>
      <reference_model_name>rover_uwb</reference_model_name>
      <reference_link_name>base_link</reference_link_name>
    </plugin>


  </model>
</sdf>
